Workbook

Sheet Fundamentals
B2: Strategy | G2: Tactics
B5: 1. Scout, never assume. | G5: 1. Every building should serve a purpose
B6: Know how many vills he's going to classical with, a higher number on gold/wood can mean he's getting a TC. If he's going for aggression, scout the type of army he's making and try to counter. General rule of thumb, find your two tc's and your second hunt pack, note your gold mines and then do the same for his. | G6: Create chokepoints, prevent raiding and treat buldings as a free wall.
G9: 2. Keep army moving OR in position
G10: If you have cavalry, keep scouting/raiding/picking off straggler troops. If you have archers keep them in secure locations to avoid losing them, chokepoints are preferable. Infantry should be placed in spots to prevent raids. If you are being aggressive, put yourself in his spot and place army ahead of time to intercept key resources.
B14: 2. Put yourself in his position
B15: Ask yourself, what would you do if you played from his POV. Where would your second food gathering spot be? Would you take a TC? Would you FH? Start thinking about this ahead of time, while you scout.
B21: 3. Only take fights that are favorable
B22: 1. If you have a clear mathmatical/techn advantage (Check before you fight, you can select units and right click and check what upgrades he has, don't fight blindly) 2. If your eco is significantly larger and you want to drain him 3. Never let a single unit die needlessly

Sheet Units
A1: Type | B1: Faction | C1: Unit | D1: Food | E1: Wood | F1: Gold | G1: Favor | H1: Cost | I1: Pop | J1: Training Time | K1: HP | L1: Hack Damage | M1: Pierce Damage | N1: Divine Damage | O1: Crush Damage | P1: Total Damage | Q1: Attack Speed | R1: Multiplier 1 | S1: Multiplier 2 | T1: Multiplier 3 | U1: Hack Armor | V1: Pierce Armor | W1: Crush Armor | X1: Range | Y1: Speed | Z1: DPS | AA1: DPS (Crush) | AB1: DPS Per Cost | AC1: DPS Per Pop | AD1: HP Per Cost | AE1: HP Per Pop | AF1: Hack HP Per Cost | AG1: Pierce HP Per Cost
A2: Animal | B2: All | C2: Golden Lion | H2: =SUM(D2:F2) -> 0 | K2: 70 | L2: 15 | P2: =SUBTOTAL(9,L2:N2) -> 15 | Q2: 2.2 | U2: 0.15 | V2: 0.2 | W2: 0.99 | Y2: 5 | Z2: =IFERROR(P2/Q2,0) -> 6.8181818 | AA2: =IFERROR(O2/Q2,0) -> 0 | AB2: =IFERROR(Z2/H2,0) -> 0 | AC2: =IFERROR(Z2/I2,0) -> 0 | AD2: =IFERROR(K2/H2,0) -> 0 | AE2: =IFERROR(K2/I2,0) -> 0 | AF2: =IFERROR((K2/(1-U2))/H2,0) -> 0 | AG2: =IFERROR((K2/(1-V2))/H2,0) -> 0
A3: Animal | B3: All | C3: Relic Monkey | H3: =SUM(D3:F3) -> 0 | K3: 40 | L3: 5 | P3: =SUBTOTAL(9,L3:N3) -> 5 | Q3: 1 | U3: 0.35 | V3: 0.2 | W3: 0.99 | Y3: 3.3 | Z3: =IFERROR(P3/Q3,0) -> 5 | AA3: =IFERROR(O3/Q3,0) -> 0 | AB3: =IFERROR(Z3/H3,0) -> 0 | AC3: =IFERROR(Z3/I3,0) -> 0 | AD3: =IFERROR(K3/H3,0) -> 0 | AE3: =IFERROR(K3/I3,0) -> 0 | AF3: =IFERROR((K3/(1-U3))/H3,0) -> 0 | AG3: =IFERROR((K3/(1-V3))/H3,0) -> 0
A4: Cavalry | B4: Egypt | C4: War Elephant | D4: 180 | F4: 70 | H4: =SUM(D4:F4) -> 250 | I4: 5 | J4: 17 | K4: 495 | L4: 22 | P4: =SUBTOTAL(9,L4:N4) -> 22 | Q4: 1.4 | R4: 3X vs. Buildings | U4: 0.25 | V4: 0.4 | W4: 0.99 | Y4: 2.9 | Z4: =IFERROR(P4/Q4,0) -> 15.714286 | AA4: =IFERROR(O4/Q4,0) -> 0 | AB4: =IFERROR(Z4/H4,0) -> 0.062857143 | AC4: =IFERROR(Z4/I4,0) -> 3.1428571 | AD4: =IFERROR(K4/H4,0) -> 1.98 | AE4: =IFERROR(K4/I4,0) -> 99 | AF4: =IFERROR((K4/(1-U4))/H4,0) -> 2.64 | AG4: =IFERROR((K4/(1-V4))/H4,0) -> 3.3
A5: Infantry | B5: Atlantean | C5: Murmillo | D5: 55 | F5: 30 | H5: =SUM(D5:F5) -> 85 | I5: 2 | J5: 14 | K5: 110 | L5: 7 | P5: =SUBTOTAL(9,L5:N5) -> 7 | Q5: 0.8 | U5: 0.4 | V5: 0.1 | W5: 0.99 | Y5: 4.5 | Z5: =IFERROR(P5/Q5,0) -> 8.75 | AA5: =IFERROR(O5/Q5,0) -> 0 | AB5: =IFERROR(Z5/H5,0) -> 0.10294118 | AC5: =IFERROR(Z5/I5,0) -> 4.375 | AD5: =IFERROR(K5/H5,0) -> 1.2941176 | AE5: =IFERROR(K5/I5,0) -> 55 | AF5: =IFERROR((K5/(1-U5))/H5,0) -> 2.1568627 | AG5: =IFERROR((K5/(1-V5))/H5,0) -> 1.4379085
A6: Myth | B6: Atlantean | C6: Argus | F6: 250 | G6: 4 | H6: =SUM(D6:F6) -> 250 | I6: 4 | J6: 30 | K6: 760 | L6: 40 | P6: =SUBTOTAL(9,L6:N6) -> 40 | Q6: 1.5 | R6: 3x MU | T6: 0,5 x Hero | U6: 0.6 | V6: 0.7 | W6: 0.8 | Y6: 4.1 | Z6: =IFERROR(P6/Q6,0) -> 26.666667 | AA6: =IFERROR(O6/Q6,0) -> 0 | AB6: =IFERROR(Z6/H6,0) -> 0.10666667 | AC6: =IFERROR(Z6/I6,0) -> 6.6666667 | AD6: =IFERROR(K6/H6,0) -> 3.04 | AE6: =IFERROR(K6/I6,0) -> 190 | AF6: =IFERROR((K6/(1-U6))/H6,0) -> 7.6 | AG6: =IFERROR((K6/(1-V6))/H6,0) -> 10.133333
A7: Myth | B7: Atlantean | C7: Automaton | F7: 90 | G7: 6 | H7: =SUM(D7:F7) -> 90 | I7: 2 | J7: 18 | K7: 230 | L7: 11 | P7: =SUBTOTAL(9,L7:N7) -> 11 | Q7: 1 | R7: 3x MU | S7: 0,5x Hero | T7: 0,5 x Hero | U7: 0.3 | V7: 0.55 | W7: 0.8 | Y7: 4.2 | Z7: =IFERROR(P7/Q7,0) -> 11 | AA7: =IFERROR(O7/Q7,0) -> 0 | AB7: =IFERROR(Z7/H7,0) -> 0.12222222 | AC7: =IFERROR(Z7/I7,0) -> 5.5 | AD7: =IFERROR(K7/H7,0) -> 2.5555556 | AE7: =IFERROR(K7/I7,0) -> 115 | AF7: =IFERROR((K7/(1-U7))/H7,0) -> 3.6507937 | AG7: =IFERROR((K7/(1-V7))/H7,0) -> 5.6790123
A8: Myth | B8: Atlantean | C8: Behemoth | D8: 250 | G8: 20 | H8: =SUM(D8:F8) -> 250 | I8: 4 | J8: 20 | K8: 650 | L8: 9 | O8: 18 | P8: =SUBTOTAL(9,L8:N8) -> 9 | Q8: 1.5 | R8: 5x Buildings | S8: 2x MU | T8: 0,5 x Hero | U8: 0.3 | V8: 0.75 | W8: 0.8 | X8: 2.5 | Y8: 3 | Z8: =IFERROR(P8/Q8,0) -> 6 | AA8: =IFERROR(O8/Q8,0) -> 12 | AB8: =IFERROR(Z8/H8,0) -> 0.024 | AC8: =IFERROR(Z8/I8,0) -> 1.5 | AD8: =IFERROR(K8/H8,0) -> 2.6 | AE8: =IFERROR(K8/I8,0) -> 162.5 | AF8: =IFERROR((K8/(1-U8))/H8,0) -> 3.7142857 | AG8: =IFERROR((K8/(1-V8))/H8,0) -> 10.4
A9: Arrow Ship | B9: Atlantean | C9: Bireme | E9: 100 | F9: 50 | H9: =SUM(D9:F9) -> 150 | I9: 3 | J9: 12 | K9: 290 | M9: =8*3 -> 24 | P9: =SUBTOTAL(9,L9:N9) -> 24 | Q9: 1.5 | U9: 0.5 | V9: 0.3 | W9: 0.05 | X9: 15 | Y9: 5.8 | Z9: =IFERROR(P9/Q9,0) -> 16 | AA9: =IFERROR(O9/Q9,0) -> 0 | AB9: =IFERROR(Z9/H9,0) -> 0.10666667 | AC9: =IFERROR(Z9/I9,0) -> 5.3333333 | AD9: =IFERROR(K9/H9,0) -> 1.9333333 | AE9: =IFERROR(K9/I9,0) -> 96.666667 | AF9: =IFERROR((K9/(1-U9))/H9,0) -> 3.8666667 | AG9: =IFERROR((K9/(1-V9))/H9,0) -> 2.7619048
A10: Myth | B10: Atlantean | C10: Caladria | E10: 100 | F10: 25 | G10: 12 | H10: =SUM(D10:F10) -> 125 | I10: 2 | J10: 9 | K10: 125 | N10: -15 | P10: =SUBTOTAL(9,L10:N10) -> -15 | Q10: 1 | T10: 0,5 x Hero | U10: 0.1 | V10: 0.2 | W10: 0.8 | Y10: 5.3 | AA10: =IFERROR(O10/Q10,0) -> 0 | AB10: =IFERROR(Z10/H10,0) -> 0 | AC10: =IFERROR(Z10/I10,0) -> 0 | AD10: =IFERROR(K10/H10,0) -> 1 | AE10: =IFERROR(K10/I10,0) -> 62.5 | AF10: =IFERROR((K10/(1-U10))/H10,0) -> 1.1111111 | AG10: =IFERROR((K10/(1-V10))/H10,0) -> 1.25
A11: Myth | B11: Atlantean | C11: Carnivora | G11: 25 | H11: =SUM(D11:F11) -> 0 | K11: 600 | L11: 20 | P11: =SUBTOTAL(9,L11:N11) -> 20 | Q11: 1 | R11: 0,5 x Hero | S11: 0,25 x Villagers | U11: 0.35 | V11: 0.2 | W11: 0.8 | Z11: =IFERROR(P11/Q11,0) -> 20 | AA11: =IFERROR(O11/Q11,0) -> 0 | AB11: =IFERROR(Z11/H11,0) -> 0 | AC11: =IFERROR(Z11/I11,0) -> 0 | AD11: =IFERROR(K11/H11,0) -> 0 | AE11: =IFERROR(K11/I11,0) -> 0 | AF11: =IFERROR((K11/(1-U11))/H11,0) -> 0 | AG11: =IFERROR((K11/(1-V11))/H11,0) -> 0
A12: Ranged Siege | B12: Atlantean | C12: Cheiroballista | E12: 115 | F12: 100 | H12: =SUM(D12:F12) -> 215 | I12: 4 | J12: 24 | K12: 85 | M12: =3*4 -> 12 | P12: =SUBTOTAL(9,L12:N12) -> 12 | Q12: 2 | R12: 4.0x infantry and 3x ships | U12: 0.25 | V12: 0.5 | W12: 0.5 | X12: 20 | Y12: 3.8 | Z12: =IFERROR(P12/Q12,0) -> 6 | AA12: =IFERROR(O12/Q12,0) -> 0 | AB12: =IFERROR(Z12/H12,0) -> 0.027906977 | AC12: =IFERROR(Z12/I12,0) -> 1.5 | AD12: =IFERROR(K12/H12,0) -> 0.39534884 | AE12: =IFERROR(K12/I12,0) -> 21.25 | AF12: =IFERROR((K12/(1-U12))/H12,0) -> 0.52713178 | AG12: =IFERROR((K12/(1-V12))/H12,0) -> 0.79069767
A13: Ranged Siege Hero | B13: Atlantean | C13: Cheiroballista (Hero) | E13: 200 | F13: 175 | G13: 4 | H13: =SUM(D13:F13) -> 375 | I13: 4 | J13: =24+8 -> 32 | K13: 115 | M13: 4 | P13: =SUBTOTAL(9,L13:N13) -> 4 | Q13: 2 | R13: 3.5x Infrantry | S13: 3x Ships | T13: 8x MU | U13: 0.25 | V13: 0.5 | W13: 0.5 | X13: 20 | Y13: 4.1 | Z13: =IFERROR(P13/Q13,0) -> 2 | AA13: =IFERROR(O13/Q13,0) -> 0 | AB13: =IFERROR(Z13/H13,0) -> 0.0053333333 | AC13: =IFERROR(Z13/I13,0) -> 0.5 | AD13: =IFERROR(K13/H13,0) -> 0.30666667 | AE13: =IFERROR(K13/I13,0) -> 28.75 | AF13: =IFERROR((K13/(1-U13))/H13,0) -> 0.40888889 | AG13: =IFERROR((K13/(1-V13))/H13,0) -> 0.61333333
A14: Infantry | B14: Greek | C14: Hoplite | D14: 50 | F14: 40 | H14: =SUM(D14:F14) -> 90 | I14: 2 | J14: 12 | K14: 115 | L14: 7.5 | P14: =SUBTOTAL(9,L14:N14) -> 7.5 | Q14: 1 | R14: 1.25x cavalry | U14: 0.4 | V14: 0.15 | W14: 0.99 | Y14: 4.3 | Z14: =IFERROR(P14/Q14,0) -> 7.5 | AA14: =IFERROR(O14/Q14,0) -> 0 | AB14: =IFERROR(Z14/H14,0) -> 0.083333333 | AC14: =IFERROR(Z14/I14,0) -> 3.75 | AD14: =IFERROR(K14/H14,0) -> 1.2777778 | AE14: =IFERROR(K14/I14,0) -> 57.5 | AF14: =IFERROR((K14/(1-U14))/H14,0) -> 2.1296296 | AG14: =IFERROR((K14/(1-V14))/H14,0) -> 1.503268
A15: Hero | B15: Atlantean | C15: Contarius (Hero) | D15: 105 | F15: 70 | G15: 3 | H15: =SUM(D15:F15) -> 175 | I15: 3 | J15: =17+8 -> 25 | K15: 155 | L15: 15 | P15: =SUBTOTAL(9,L15:N15) -> 15 | Q15: 1.5 | R15: 1,5x Ranged | S15: 7x MU | U15: 0.15 | V15: 0.4 | W15: 0.99 | X15: 1 | Y15: 6.1 | Z15: =IFERROR(P15/Q15,0) -> 10 | AA15: =IFERROR(O15/Q15,0) -> 0 | AB15: =IFERROR(Z15/H15,0) -> 0.057142857 | AC15: =IFERROR(Z15/I15,0) -> 3.3333333 | AD15: =IFERROR(K15/H15,0) -> 0.88571429 | AE15: =IFERROR(K15/I15,0) -> 51.666667 | AF15: =IFERROR((K15/(1-U15))/H15,0) -> 1.0420168 | AG15: =IFERROR((K15/(1-V15))/H15,0) -> 1.4761905
A16: Siege Infantry | B16: Atlantean | C16: Destroyer | D16: 70 | F16: 60 | H16: =SUM(D16:F16) -> 130 | I16: 3 | J16: 11 | K16: 150 | L16: 6 | P16: =SUBTOTAL(9,L16:N16) -> 6 | Q16: 1.2 | R16: 6x buildings | U16: 0.3 | V16: 0.7 | W16: 0.99 | X16: 1.5 | Y16: 3.6 | Z16: =IFERROR(P16/Q16,0) -> 5 | AA16: =IFERROR(O16/Q16,0) -> 0 | AB16: =IFERROR(Z16/H16,0) -> 0.038461538 | AC16: =IFERROR(Z16/I16,0) -> 1.6666667 | AD16: =IFERROR(K16/H16,0) -> 1.1538462 | AE16: =IFERROR(K16/I16,0) -> 50 | AF16: =IFERROR((K16/(1-U16))/H16,0) -> 1.6483516 | AG16: =IFERROR((K16/(1-V16))/H16,0) -> 3.8461538
A17: Siege Infantry Hero | B17: Atlantean | C17: Destroyer (Hero) | D17: 125 | F17: 105 | G17: 3 | H17: =SUM(D17:F17) -> 230 | I17: 3 | J17: =11+8 -> 19 | K17: 165 | L17: 3.9 | P17: =SUBTOTAL(9,L17:N17) -> 3.9 | Q17: 1.2 | R17: 6x Building | S17: 11x MU | U17: 0.3 | V17: 0.7 | W17: 0.99 | Y17: 3.9 | Z17: =IFERROR(P17/Q17,0) -> 3.25 | AA17: =IFERROR(O17/Q17,0) -> 0 | AB17: =IFERROR(Z17/H17,0) -> 0.014130435 | AC17: =IFERROR(Z17/I17,0) -> 1.0833333 | AD17: =IFERROR(K17/H17,0) -> 0.7173913 | AE17: =IFERROR(K17/I17,0) -> 55 | AF17: =IFERROR((K17/(1-U17))/H17,0) -> 1.0248447 | AG17: =IFERROR((K17/(1-V17))/H17,0) -> 2.3913043
A18: Myth | B18: Atlantean | C18: Dryad | E18: 150 | H18: =SUM(D18:F18) -> 150 | I18: 0 | J18: 8 | K18: 275 | L18: 22 | P18: =SUBTOTAL(9,L18:N18) -> 22 | Q18: 1.5 | R18: 0,5 x Hero | U18: 0.4 | V18: 0.5 | W18: 0.8 | Y18: 4.5 | Z18: =IFERROR(P18/Q18,0) -> 14.666667 | AA18: =IFERROR(O18/Q18,0) -> 0 | AB18: =IFERROR(Z18/H18,0) -> 0.097777778 | AC18: =IFERROR(Z18/I18,0) -> 0 | AD18: =IFERROR(K18/H18,0) -> 1.8333333 | AE18: =IFERROR(K18/I18,0) -> 0 | AF18: =IFERROR((K18/(1-U18))/H18,0) -> 3.0555556 | AG18: =IFERROR((K18/(1-V18))/H18,0) -> 3.6666667
A19: Infantry | B19: Atlantean | C19: Katapeltes | D19: 60 | F19: 35 | H19: =SUM(D19:F19) -> 95 | I19: 2 | J19: 11 | K19: 115 | L19: 6 | P19: =SUBTOTAL(9,L19:N19) -> 6 | Q19: 1.2 | R19: 4x cavalry | U19: 0.35 | V19: 0.1 | W19: 0.99 | Y19: 4.5 | Z19: =IFERROR(P19/Q19,0) -> 5 | AA19: =IFERROR(O19/Q19,0) -> 0 | AB19: =IFERROR(Z19/H19,0) -> 0.052631579 | AC19: =IFERROR(Z19/I19,0) -> 2.5 | AD19: =IFERROR(K19/H19,0) -> 1.2105263 | AE19: =IFERROR(K19/I19,0) -> 57.5 | AF19: =IFERROR((K19/(1-U19))/H19,0) -> 1.8623482 | AG19: =IFERROR((K19/(1-V19))/H19,0) -> 1.3450292
A20: Hero | B20: Atlantean | C20: Fanatic (Hero) | D20: 130 | F20: 95 | G20: 3 | H20: =SUM(D20:F20) -> 225 | I20: 3 | J20: =11+8 -> 19 | K20: 155 | L20: 9 | P20: =SUBTOTAL(9,L20:N20) -> 9 | Q20: 1 | R20: 2x Infrantry | S20: 2x Cavalry | T20: 8x MU | U20: 0.4 | V20: 0.15 | W20: 0.99 | Y20: 4.6 | Z20: =IFERROR(P20/Q20,0) -> 9 | AA20: =IFERROR(O20/Q20,0) -> 0 | AB20: =IFERROR(Z20/H20,0) -> 0.04 | AC20: =IFERROR(Z20/I20,0) -> 3 | AD20: =IFERROR(K20/H20,0) -> 0.68888889 | AE20: =IFERROR(K20/I20,0) -> 51.666667 | AF20: =IFERROR((K20/(1-U20))/H20,0) -> 1.1481481 | AG20: =IFERROR((K20/(1-V20))/H20,0) -> 0.81045752
A21: Close Combat Ship | B21: Atlantean | C21: Fire Ship | E21: 100 | F21: 50 | H21: =SUM(D21:F21) -> 150 | I21: 3 | J21: 17 | K21: 320 | L21: 20 | P21: =SUBTOTAL(9,L21:N21) -> 20 | Q21: 1.5 | U21: 0.3 | V21: 0.1 | W21: 0.5 | X21: 5 | Y21: 7.3 | Z21: =IFERROR(P21/Q21,0) -> 13.333333 | AA21: =IFERROR(O21/Q21,0) -> 0 | AB21: =IFERROR(Z21/H21,0) -> 0.088888889 | AC21: =IFERROR(Z21/I21,0) -> 4.4444444 | AD21: =IFERROR(K21/H21,0) -> 2.1333333 | AE21: =IFERROR(K21/I21,0) -> 106.66667 | AF21: =IFERROR((K21/(1-U21))/H21,0) -> 3.047619 | AG21: =IFERROR((K21/(1-V21))/H21,0) -> 2.3703704
A22: Siege | B22: Atlantean | C22: Fire Siphon | E22: 275 | F22: 180 | H22: =SUM(D22:F22) -> 455 | I22: 5 | J22: 19 | K22: 350 | M22: 20 | O22: 100 | P22: =SUBTOTAL(9,L22:N22) -> 20 | Q22: 1.7 | U22: 0.05 | V22: 0.9 | W22: 0.5 | X22: 16 | Y22: 2.9 | Z22: =IFERROR(P22/Q22,0) -> 11.764706 | AA22: =IFERROR(O22/Q22,0) -> 58.823529 | AB22: =IFERROR(Z22/H22,0) -> 0.025856496 | AC22: =IFERROR(Z22/I22,0) -> 2.3529412 | AD22: =IFERROR(K22/H22,0) -> 0.76923077 | AE22: =IFERROR(K22/I22,0) -> 70 | AF22: =IFERROR((K22/(1-U22))/H22,0) -> 0.8097166 | AG22: =IFERROR((K22/(1-V22))/H22,0) -> 7.6923077
A23: Cavalry | B23: Norse | C23: Jarl | D23: 50 | F23: 80 | H23: =SUM(D23:F23) -> 130 | I23: 3 | J23: 24 | K23: 180 | L23: 10 | P23: =SUBTOTAL(9,L23:N23) -> 10 | Q23: 1 | U23: 0.25 | V23: 0.35 | W23: 0.99 | Y23: 4.8 | Z23: =IFERROR(P23/Q23,0) -> 10 | AA23: =IFERROR(O23/Q23,0) -> 0 | AB23: =IFERROR(Z23/H23,0) -> 0.076923077 | AC23: =IFERROR(Z23/I23,0) -> 3.3333333 | AD23: =IFERROR(K23/H23,0) -> 1.3846154 | AE23: =IFERROR(K23/I23,0) -> 60 | AF23: =IFERROR((K23/(1-U23))/H23,0) -> 1.8461538 | AG23: =IFERROR((K23/(1-V23))/H23,0) -> 2.1301775
A24: Hero | B24: Atlantean | C24: Katapeltes (Hero) | D24: 105 | F24: 60 | G24: 2 | H24: =SUM(D24:F24) -> 165 | I24: 2 | J24: =11+8 -> 19 | K24: 130 | L24: 7 | P24: =SUBTOTAL(9,L24:N24) -> 7 | Q24: 1.2 | R24: 4x Cavalry | S24: 9x MU | U24: 0.35 | V24: 0.1 | W24: 0.99 | Y24: 4.8 | Z24: =IFERROR(P24/Q24,0) -> 5.8333333 | AA24: =IFERROR(O24/Q24,0) -> 0 | AB24: =IFERROR(Z24/H24,0) -> 0.035353535 | AC24: =IFERROR(Z24/I24,0) -> 2.9166667 | AD24: =IFERROR(K24/H24,0) -> 0.78787879 | AE24: =IFERROR(K24/I24,0) -> 65 | AF24: =IFERROR((K24/(1-U24))/H24,0) -> 1.2121212 | AG24: =IFERROR((K24/(1-V24))/H24,0) -> 0.87542088
A25: Myth | B25: Atlantean | C25: Lampades | F25: 250 | G25: 25 | H25: =SUM(D25:F25) -> 250 | I25: 4 | J25: 20 | K25: 350 | M25: 24 | O25: 20 | P25: =SUBTOTAL(9,L25:N25) -> 24 | Q25: 2 | R25: 2x MU | S25: 0,25x Hero | T25: 0,5 x Hero | U25: 0.4 | V25: 0.5 | W25: 0.8 | X25: 12 | Y25: 4.3 | Z25: =IFERROR(P25/Q25,0) -> 12 | AA25: =IFERROR(O25/Q25,0) -> 10 | AB25: =IFERROR(Z25/H25,0) -> 0.048 | AC25: =IFERROR(Z25/I25,0) -> 3 | AD25: =IFERROR(K25/H25,0) -> 1.4 | AE25: =IFERROR(K25/I25,0) -> 87.5 | AF25: =IFERROR((K25/(1-U25))/H25,0) -> 2.3333333 | AG25: =IFERROR((K25/(1-V25))/H25,0) -> 2.8
A26: Myth | B26: Atlantean | C26: Man O War | D26: 250 | G26: 15 | H26: =SUM(D26:F26) -> 250 | I26: 4 | J26: 10 | K26: 900 | N26: 25 | P26: =SUBTOTAL(9,L26:N26) -> 25 | Q26: 3 | R26: 3x MU | S26: 0,25x Hero | T26: 0,25 x Hero | U26: 0.5 | V26: 0.7 | W26: 0.8 | X26: 12 | Y26: 6 | Z26: =IFERROR(P26/Q26,0) -> 8.3333333 | AA26: =IFERROR(O26/Q26,0) -> 0 | AB26: =IFERROR(Z26/H26,0) -> 0.033333333 | AC26: =IFERROR(Z26/I26,0) -> 2.0833333 | AD26: =IFERROR(K26/H26,0) -> 3.6 | AE26: =IFERROR(K26/I26,0) -> 225 | AF26: =IFERROR((K26/(1-U26))/H26,0) -> 7.2 | AG26: =IFERROR((K26/(1-V26))/H26,0) -> 12
A27: Infantry | B27: Atlantean | C27: Fanatic | D27: 75 | F27: 55 | H27: =SUM(D27:F27) -> 130 | I27: 3 | J27: 11 | K27: 140 | L27: 8 | P27: =SUBTOTAL(9,L27:N27) -> 8 | Q27: 1 | R27: 2x infantry 2x cavalry | U27: 0.4 | V27: 0.15 | W27: 0.99 | Y27: 4.3 | Z27: =IFERROR(P27/Q27,0) -> 8 | AA27: =IFERROR(O27/Q27,0) -> 0 | AB27: =IFERROR(Z27/H27,0) -> 0.061538462 | AC27: =IFERROR(Z27/I27,0) -> 2.6666667 | AD27: =IFERROR(K27/H27,0) -> 1.0769231 | AE27: =IFERROR(K27/I27,0) -> 46.666667 | AF27: =IFERROR((K27/(1-U27))/H27,0) -> 1.7948718 | AG27: =IFERROR((K27/(1-V27))/H27,0) -> 1.2669683
A28: Infantry Hero | B28: Atlantean | C28: Murmillo (Hero) | D28: 95 | F28: 55 | G28: 2 | H28: =SUM(D28:F28) -> 150 | I28: 2 | J28: 22 | K28: 125 | L28: 8 | M28: 10 | P28: =SUBTOTAL(9,L28:N28) -> 18 | Q28: 0.8 | R28: 5,5x MU | U28: 0.4 | V28: 0.1 | W28: 0.99 | Y28: 4.8 | Z28: =IFERROR(P28/Q28,0) -> 22.5 | AA28: =IFERROR(O28/Q28,0) -> 0 | AB28: =IFERROR(Z28/H28,0) -> 0.15 | AC28: =IFERROR(Z28/I28,0) -> 11.25 | AD28: =IFERROR(K28/H28,0) -> 0.83333333 | AE28: =IFERROR(K28/I28,0) -> 62.5 | AF28: =IFERROR((K28/(1-U28))/H28,0) -> 1.3888889 | AG28: =IFERROR((K28/(1-V28))/H28,0) -> 0.92592593
A29: Myth | B29: Atlantean | C29: Nerid | F29: 200 | G29: 15 | H29: =SUM(D29:F29) -> 200 | I29: 2 | J29: 12 | K29: 400 | L29: 25 | P29: =SUBTOTAL(9,L29:N29) -> 25 | Q29: 1 | R29: 2x MU | S29: 0,5x Hero | T29: 0,5 x Hero | U29: 0.3 | V29: 0.5 | W29: 0.8 | Y29: 5 | Z29: =IFERROR(P29/Q29,0) -> 25 | AA29: =IFERROR(O29/Q29,0) -> 0 | AB29: =IFERROR(Z29/H29,0) -> 0.125 | AC29: =IFERROR(Z29/I29,0) -> 12.5 | AD29: =IFERROR(K29/H29,0) -> 2 | AE29: =IFERROR(K29/I29,0) -> 200 | AF29: =IFERROR((K29/(1-U29))/H29,0) -> 2.8571429 | AG29: =IFERROR((K29/(1-V29))/H29,0) -> 4
A30: Infantry | B30: Egypt | C30: Spearman | D30: 50 | F30: 20 | H30: =SUM(D30:F30) -> 70 | I30: 2 | J30: 12 | K30: 75 | L30: 6 | P30: =SUBTOTAL(9,L30:N30) -> 6 | Q30: 1 | R30: 1.75x cavalry | U30: 0.4 | V30: 0.15 | W30: 0.99 | Y30: 5 | Z30: =IFERROR(P30/Q30,0) -> 6 | AA30: =IFERROR(O30/Q30,0) -> 0 | AB30: =IFERROR(Z30/H30,0) -> 0.085714286 | AC30: =IFERROR(Z30/I30,0) -> 3 | AD30: =IFERROR(K30/H30,0) -> 1.0714286 | AE30: =IFERROR(K30/I30,0) -> 37.5 | AF30: =IFERROR((K30/(1-U30))/H30,0) -> 1.7857143 | AG30: =IFERROR((K30/(1-V30))/H30,0) -> 1.2605042
A31: Hero | B31: Atlantean | C31: Oracle (Hero) | D31: 80 | F31: 120 | G31: 1 | H31: =SUM(D31:F31) -> 200 | I31: 1 | J31: =11+8 -> 19 | K31: 105 | L31: 9 | P31: =SUBTOTAL(9,L31:N31) -> 9 | Q31: 1.5 | R31: 6x MU | U31: 0.2 | V31: 0.5 | W31: 0.99 | Y31: 4.2 | Z31: =IFERROR(P31/Q31,0) -> 6 | AA31: =IFERROR(O31/Q31,0) -> 0 | AB31: =IFERROR(Z31/H31,0) -> 0.03 | AC31: =IFERROR(Z31/I31,0) -> 6 | AD31: =IFERROR(K31/H31,0) -> 0.525 | AE31: =IFERROR(K31/I31,0) -> 105 | AF31: =IFERROR((K31/(1-U31))/H31,0) -> 0.65625 | AG31: =IFERROR((K31/(1-V31))/H31,0) -> 1.05
A32: Myth | B32: Atlantean | C32: Promethean | D32: 90 | G32: 8 | H32: =SUM(D32:F32) -> 90 | I32: 2 | J32: 18 | K32: 175 | L32: 12 | P32: =SUBTOTAL(9,L32:N32) -> 12 | Q32: 1.1 | R32: 3x MU | S32: 0,5x Hero | T32: 0,5 x Hero | U32: 0.6 | V32: 0.25 | W32: 0.8 | Y32: 4.3 | Z32: =IFERROR(P32/Q32,0) -> 10.909091 | AA32: =IFERROR(O32/Q32,0) -> 0 | AB32: =IFERROR(Z32/H32,0) -> 0.12121212 | AC32: =IFERROR(Z32/I32,0) -> 5.4545455 | AD32: =IFERROR(K32/H32,0) -> 1.9444444 | AE32: =IFERROR(K32/I32,0) -> 87.5 | AF32: =IFERROR((K32/(1-U32))/H32,0) -> 4.8611111 | AG32: =IFERROR((K32/(1-V32))/H32,0) -> 2.5925926
A33: Myth | B33: Atlantean | C33: Promethean (off spring) | D33: 45 | G33: 4 | H33: =SUM(D33:F33) -> 45 | I33: 1 | K33: 80 | L33: 6 | P33: =SUBTOTAL(9,L33:N33) -> 6 | Q33: 1.1 | R33: 1,5xMU | S33: 0,5x Hero | T33: 0,5 x Hero | U33: 0.25 | V33: 0.35 | W33: 0.8 | Y33: 5.5 | Z33: =IFERROR(P33/Q33,0) -> 5.4545455 | AA33: =IFERROR(O33/Q33,0) -> 0 | AB33: =IFERROR(Z33/H33,0) -> 0.12121212 | AC33: =IFERROR(Z33/I33,0) -> 5.4545455 | AD33: =IFERROR(K33/H33,0) -> 1.7777778 | AE33: =IFERROR(K33/I33,0) -> 80 | AF33: =IFERROR((K33/(1-U33))/H33,0) -> 2.3703704 | AG33: =IFERROR((K33/(1-V33))/H33,0) -> 2.7350427
A34: Myth | B34: Atlantean | C34: Satyr | E34: 250 | G34: 20 | H34: =SUM(D34:F34) -> 250 | I34: 3 | J34: 15 | K34: 400 | M34: 20 | P34: =SUBTOTAL(9,L34:N34) -> 20 | Q34: 1 | R34: 3xMU | S34: 0,25 x Hero | T34: 0,25 x Villagers | U34: 0.5 | V34: 0.5 | W34: 0.8 | X34: 18 | Y34: 3.8 | Z34: =IFERROR(P34/Q34,0) -> 20 | AA34: =IFERROR(O34/Q34,0) -> 0 | AB34: =IFERROR(Z34/H34,0) -> 0.08 | AC34: =IFERROR(Z34/I34,0) -> 6.6666667 | AD34: =IFERROR(K34/H34,0) -> 1.6 | AE34: =IFERROR(K34/I34,0) -> 133.33333 | AF34: =IFERROR((K34/(1-U34))/H34,0) -> 3.2 | AG34: =IFERROR((K34/(1-V34))/H34,0) -> 3.2
A35: Arrow Ship | B35: Atlantean | C35: Siege Bireme | E35: 100 | F35: 50 | H35: =SUM(D35:F35) -> 150 | I35: 3 | J35: 17 | K35: 250 | M35: =2*4 -> 8 | O35: 4*4 | P35: =SUBTOTAL(9,L35:N35) -> 8 | Q35: 2 | R35: 2x Archer Ships | U35: 0.1 | V35: 0.6 | W35: 0.1 | X35: 20 | Y35: 5.1 | Z35: =IFERROR(P35/Q35,0) -> 4 | AA35: =IFERROR(O35/Q35,0) -> 0 | AB35: =IFERROR(Z35/H35,0) -> 0.026666667 | AC35: =IFERROR(Z35/I35,0) -> 1.3333333 | AD35: =IFERROR(K35/H35,0) -> 1.6666667 | AE35: =IFERROR(K35/I35,0) -> 83.333333 | AF35: =IFERROR((K35/(1-U35))/H35,0) -> 1.8518519 | AG35: =IFERROR((K35/(1-V35))/H35,0) -> 4.1666667
A36: Myth | B36: Atlantean | C36: Stymphalian Bird | E36: 200 | F36: 20 | G36: 25 | H36: =SUM(D36:F36) -> 220 | I36: 3 | J36: 10 | K36: 400 | M36: =14*3 -> 42 | P36: =SUBTOTAL(9,L36:N36) -> 42 | Q36: 1.8 | R36: 3x MU | S36: 0,25x Hero | U36: 0.15 | V36: 0.45 | W36: 0.8 | X36: 15 | Y36: 3.8 | Z36: =IFERROR(P36/Q36,0) -> 23.333333 | AA36: =IFERROR(O36/Q36,0) -> 0 | AB36: =IFERROR(Z36/H36,0) -> 0.10606061 | AC36: =IFERROR(Z36/I36,0) -> 7.7777778 | AD36: =IFERROR(K36/H36,0) -> 1.8181818 | AE36: =IFERROR(K36/I36,0) -> 133.33333 | AF36: =IFERROR((K36/(1-U36))/H36,0) -> 2.1390374 | AG36: =IFERROR((K36/(1-V36))/H36,0) -> 3.3057851
A37: Myth | B37: Atlantean | C37: Tartarian Spawn | H37: =SUM(D37:F37) -> 0 | K37: 350 | L37: 15 | O37: 20 | P37: =SUBTOTAL(9,L37:N37) -> 15 | Q37: 1 | R37: 2x MU | S37: 0,25x Hero | U37: 0.4 | V37: 0.4 | W37: 0.8 | Y37: 3.8 | Z37: =IFERROR(P37/Q37,0) -> 15 | AA37: =IFERROR(O37/Q37,0) -> 20 | AB37: =IFERROR(Z37/H37,0) -> 0 | AC37: =IFERROR(Z37/I37,0) -> 0 | AD37: =IFERROR(K37/H37,0) -> 0 | AE37: =IFERROR(K37/I37,0) -> 0 | AF37: =IFERROR((K37/(1-U37))/H37,0) -> 0 | AG37: =IFERROR((K37/(1-V37))/H37,0) -> 0
A38: Infantry | B38: Norse | C38: Hirdman | D38: 35 | F38: 45 | H38: =SUM(D38:F38) -> 80 | I38: 2 | J38: 14 | K38: 90 | L38: 4 | P38: =SUBTOTAL(9,L38:N38) -> 4 | Q38: 1 | R38: 4x cavalry | U38: 0.35 | V38: 0.05 | W38: 0.99 | Y38: 4.8 | Z38: =IFERROR(P38/Q38,0) -> 4 | AA38: =IFERROR(O38/Q38,0) -> 0 | AB38: =IFERROR(Z38/H38,0) -> 0.05 | AC38: =IFERROR(Z38/I38,0) -> 2 | AD38: =IFERROR(K38/H38,0) -> 1.125 | AE38: =IFERROR(K38/I38,0) -> 45 | AF38: =IFERROR((K38/(1-U38))/H38,0) -> 1.7307692 | AG38: =IFERROR((K38/(1-V38))/H38,0) -> 1.1842105
A39: Hero | B39: Atlantean | C39: Turma (Hero) | E39: 80 | F39: 70 | G39: 2 | H39: =SUM(D39:F39) -> 150 | I39: 2 | J39: 10+8 | K39: 90 | M39: 7 | P39: =SUBTOTAL(9,L39:N39) -> 7 | Q39: 1.8 | R39: 4x Ranged | S39: 8x MU | U39: 0.15 | V39: 0.4 | W39: 0.99 | X39: 12 | Y39: 5.8 | Z39: =IFERROR(P39/Q39,0) -> 3.8888889 | AA39: =IFERROR(O39/Q39,0) -> 0 | AB39: =IFERROR(Z39/H39,0) -> 0.025925926 | AC39: =IFERROR(Z39/I39,0) -> 1.9444444 | AD39: =IFERROR(K39/H39,0) -> 0.6 | AE39: =IFERROR(K39/I39,0) -> 45 | AF39: =IFERROR((K39/(1-U39))/H39,0) -> 0.70588235 | AG39: =IFERROR((K39/(1-V39))/H39,0) -> 1
A40: Myth Unit | B40: Atlantean | C40: Water Carnivora | H40: =SUM(D40:F40) -> 0 | K40: 550 | L40: 30 | P40: =SUBTOTAL(9,L40:N40) -> 30 | Q40: 1 | R40: 0,25 x Hero | S40: 0,25 x Villagers | U40: 0.35 | V40: 0.3 | W40: 0.3 | Z40: =IFERROR(P40/Q40,0) -> 30 | AA40: =IFERROR(O40/Q40,0) -> 0 | AB40: =IFERROR(Z40/H40,0) -> 0 | AC40: =IFERROR(Z40/I40,0) -> 0 | AD40: =IFERROR(K40/H40,0) -> 0 | AE40: =IFERROR(K40/I40,0) -> 0 | AF40: =IFERROR((K40/(1-U40))/H40,0) -> 0 | AG40: =IFERROR((K40/(1-V40))/H40,0) -> 0
...

Sheet Unit Tester
A1: Unit | B1: Cost | C1: # of Units | D1: Total Cost
A2: Argus | B2: =_xlfn.XLOOKUP(A2,Units!C:C,Units!H:H,"error",0) -> 250 | C2: 11 | D2: =B2*C2 -> 2750
B3: =_xlfn.XLOOKUP(A3,Units!C:C,Units!H:H,"error",0) -> 0 | C3: 5 | D3: =B3*C3 -> 0
B4: =_xlfn.XLOOKUP(A4,Units!C:C,Units!H:H,"error",0) -> 0 | C4: 3 | D4: =B4*C4 -> 0
D5: =SUM(D2:D4) -> 2750
A7: Toxotes | B7: =_xlfn.XLOOKUP(A7,Units!C:C,Units!H:H,"error",0) -> 90 | C7: 11 | D7: =B7*C7 -> 990
B8: =_xlfn.XLOOKUP(A8,Units!C:C,Units!H:H,"error",0) -> 0 | C8: 1 | D8: =B8*C8 -> 0
B9: =_xlfn.XLOOKUP(A9,Units!C:C,Units!H:H,"error",0) -> 0 | C9: 16 | D9: =B9*C9 -> 0
D10: =SUM(D7:D9) -> 990
D14: =SUM(D10:D13) -> 990

Sheet Upgrades
A1: Faction | B1: Upgrade | C1: Food | D1: Wood | E1: Gold | F1: Favor | G1: Time | H1: Description
A2: Zeus | B2: Olympus Parentage | C2: 100 | F2: 10 | G2: 40 | H2: Hero hitpoints +25% and training time -50%
A3: Athena | B3: Labyrinth of Minos | D3: 250 | F3: 20 | G3: 30 | H3: 20% speed, 30% hitpoints
A4: Athena | B4: Aegis Shield | D4: 150 | F4: 15 | G4: 40 | H4: Infantry +15% pierce
A5: Athena | B5: Sarissa | D5: 100 | F5: 15 | G5: 15 | H5: 10% damage and 1.5 additional range for hoplites
A6: Hermes | B6: Sylvan Lore | D6: 300 | F6: 20 | G6: 20 | H6: 3 additional range + 35% hitpoints
A7: Hermes | B7: Spirited Charge | C7: 125 | F7: 25 | G7: 40 | H7: 10% cavalry/centaur speed and damage
A8: Hermes | B8: Winged Messenger | E8: 50 | F8: 3 | G8: 30 | H8: respawning pegasus + 20% speed and 6 LOS
A9: Ares | B9: Deimos Sword of Dread | E9: 150 | F9: 10 | G9: 40 | H9: Hypapist enabled age 2 and +15% damage
A10: Ares | B10: Phobos Spear of Panic | C10: 100 | F10: 15 | G10: 40 | H10: hoplite, militia and prodromo get +1 divine damage
A11: Ares | B11: Will of Kronos | C11: 200 | F11: 15 | G11: 40 | H11: more damage + increased throw area
A12: Ares | B12: Enyo Bow of Horror | D12: 125 | F12: 12 | G12: 40 | H12: Toxotes +10% damage

Sheet Zeus
B1: Fast TC
B2: Opener: 3 vills to food 1 to wood (put this close to food, for easy transition)
B3: Following 2 vills to gold
B4: Remaining vills to food (9)
B5: After 9 food, 1 gold.
B6: Build temple when mine goes down to 2899
B7: You should start advancing at 16 pop (15 vills)
B8: (3 on food while you advance is okay if you're hunting)
B9: you can do an even distribution of gold/wood. Gold vills will move out to tc. (2550 for tc)
B10: TC drops at 3:55 with hero, finishes before 5 minutes with 6 vills

Sheet Hades
B1: Fast TC
B2: Opener: 3 vills to food 1 to wood (put this close to food, for easy transition)
B3: Following 2 vills to gold
B4: Remaining vills to food (10)
B5: After 10 food, 1 gold.
B6: Build temple when mine goes down to 2899
B7: You should start advancing at 16 pop (15 vills)
B8: (3 on food while you advance is okay if you're hunting)
B9: you can do an even distribution of gold/wood. Gold vills will move out to tc. (2550 for tc)
B10: TC drops around 3:55 with hero, finishes before 5 minutes with 6 vills

Sheet Poseidon
B1: Fast TC
B2: Opener: lure at hunt, all 4 vills go there
B3: Following 2 vills to gold
B4: Remaining vills to food (7)
B5: After 7 food, 3 to gold (5 total) and 1 to wood
B6: Build temple when mine goes down to 2900
B7: You should start advancing at 15 pop
B8: leave only 1 on food, go all wood and then move back after tc goes up
B9: (2550 gold)
B10: TC drops around 3:40, finishes before 4:40 minutes with 5 vills

Sheet Set
A1: 2 Anubites and TC
A2: first 3 vills go to hunting
A3: next vill to monument then to house then to gold
A4: 2 gold
A5: rest to food until 9
A6: rush up the temple with all 3 vills
A7: remaining vills to gold
A8: force drop food once temple is complete and advance
A9: transition all but 3 of your vills to gold and then get a second anubite right away
A10: Advance time 3:45, TC can drop at 3:50

Sheet Isis
A1: Standard Isis | B1: X means every new vill goes here
B2: Food | C2: Wood | D2: Gold
A3: first 3 vills go to hunting | B3: 3 | C3: 0 | D3: 0
A4: next 2 vills to gold | B4: 3 | C4: 0 | D4: 2
A5: next vill makes monument and then goes to gold as well | B5: 3 | C5: 0 | D5: 3
A6: rest to food until 7 | B6: 7 | C6: 0 | D6: 3
A7: after 7 on food, put 1 on wood and then rest on gold | B7: 7 | C7: 1 | D7: X
A8: put temple down right away, make with 1 vill | B8: 7 | C8: 1 | D8: X
A9: once temple is done, don’t make anymore vills, force drop food and advance | B9: 7 | C9: 1 | D9: X
A10: get pickaxe asap and flood of nile asap, while advancing get second monument | B10: 7 | C10: 1 | D10: X
A11: cast prosperity while advancing | B11: 7 | C11: 1 | D11: X
A12: Advance time: 4.15, TC drops at 4:20

Sheet Ra
A1: I don't use this one anymore, It's outdated
A2: Standard Ra (vill center + rain)
A3: first 3 vills go to hunting
A4: next vill makes monument and then goes to gold as well
A5: 2 to gold
A6: rest to food until 9
A7: after 9 on food, rest go straight to gold
A8: as soon as you have 150 gold for temple, make it with 2 vills, at the same time make a house
A9: at 16 population you want to drop off all your food and advance
A10: keep 3 on food, rest on gold and put your pharoah on gold to empower and priest on food
A11: once advanced, vill center on chicken and move 4 from gold to wood
A12: from this point on, get pickaxe, shaduf, husbandary and plow
... A14: Advance time 3:45, TC can drop at 3:50

Sheet Thor
A1: Armory Opener
A2: First 3 dwarves to gold, add one more dwarf. Make armory near gold mine.
A3: 2 vills to wood, then a dwarf goes to wood
A4: Research copper mail first, then pierce armor and then hammer
A5: After this I improvise, I will do a video later on with a precise build

Sheet Odin
A1: Standard Opener | B1: Total Distribution (X means all vills go here)
B2: Food | C2: Wood | D2: Gold
A3: First 2 vills go to hunting, one vill works on an oxcart for gold, then an oxcart for wood and then goes to wood | B3: 2 | C3: 1 | D3: 0
A4: make a dwarf to start with, put on gold | B4: 2 | C4: 1 | D4: 1
A5: make 2 gathererers, put on food | B5: 4 | C5: 1 | D5: 1
A6: make a dwarf to gold | B6: 4 | C6: 1 | D6: 2
A7: make a gatherer to wood | B7: 4 | C7: 2 | D7: 2
A8: make a gatherer to food | B8: 5 | C8: 2 | D8: 2
A9: make a dwarf to gold | B9: 5 | C9: 2 | D9: 3
A10: 2 gatherers to food | B10: 7 | C10: 2 | D10: 3
A11: 2 gatherers to wood | B11: 7 | C11: 4 | D11: 3
A12: 1 to dwarf | B12: 7 | C12: 4 | D12: 4
A13: Advance (might need to force drop food) | B13: 7 | C13: 4 | D13: 4
A14: Advance time 4:00~

Sheet Loki
A1: Standard Opener | B1: Total Distribution (X means all vills go here)
B2: Food | C2: Wood | D2: Gold
A3: First 2 vills go to hunting, one vill works on an oxcart for gold, then an oxcart for wood and then goes to wood | B3: 2 | C3: 1 | D3: 0
A4: make a dwarf to start with, put on gold | B4: 2 | C4: 1 | D4: 1
A5: make 2 gathererers, put on food | B5: 4 | C5: 1 | D5: 1
A6: make a dwarf to gold | B6: 4 | C6: 1 | D6: 2
A7: make a gatherer to food | B7: 5 | C7: 1 | D7: 2
A8: make a gatherer to gold | B8: 5 | C8: 1 | D8: 3
A9: make a dwarf to gold | B9: 5 | C9: 1 | D9: 4
A10: 2 gatherers to food | B10: 7 | C10: 1 | D10: 4
A11: 1 gatherer to wood (also switch the gatherer on gold to wood) | B11: 7 | C11: 3 | D11: 3
A12: 1 to dwarf | B12: 7 | C12: 3 | D12: 4
A13: Advance (might need to force drop food, also I'd take one off food and put him to wood when you're up) | B13: 6 | C13: 4 | D13: 4
A14: Advance time 3:50~

Sheet Freyr
B1: Standard Opener
C2: Food | D2: Wood | E2: Gold
B3: First 3 to food, research pickaxe, build an additional oxcart near your hunt | C3: 3 | D3: 0 | E3: 0
B4: Dwarf to gold | C4: 3 | D4: 0 | E4: 1
B5: Vill to wood | C5: 3 | D5: 1 | E5: 1
B6: Vill to food | C6: 4 | D6: 1 | E6: 1
B7: Dwarf to gold (research handaxe) | C7: 4 | D7: 1 | E7: 2
B8: Vill to wood | C8: 4 | D8: 2 | E8: 2
B9: Vill to food | C9: 5 | D9: 2 | E9: 2
B10: Vill to food | C10: 6 | D10: 2 | E10: 2
B11: Dwarf to gold | C11: 6 | D11: 2 | E11: 3
B12: Vill to food | C12: 7 | D12: 2 | E12: 3
B13: Vill to food | C13: 8 | D13: 2 | E13: 3
B14: Vill to wood | C14: 8 | D14: 3 | E14: 3
... B16: Dwarf to gold | C16: 8 | D16: 4 | E16: 4
B17: Advance to the next age (I recommend Freya for scouting purposes)
B18: Advance time 4:15~

Sheet Kronos
A1: Fast second tc | B1: Total Distribution (X means all vills go here)
A2: Description | B2: Food | C2: Wood | D2: Gold
A3: 2 citizens to food | B3: 2 | C3: 0 | D3: 0
A4: 1 citizen to food. Build manor, shift it back to the gold mine | B4: 3 | C4: 0 | D4: 0
A5: 1 to gold | B5: 3 | C5: 0 | D5: 1
A6: 1 to wood | B6: 3 | C6: 1 | D6: 1
A7: rest to food | B7: X | C7: 1 | D7: 1
A8: build temple with two vills.
A9: After you start advancing, put 4 on gold, 3 on wood.
A10: Start advancing at 2:30, advance around 3:30
A11: Timeshift temple to opponents base, distract him . Timeshift manor to second tc
A12: Take second tc with 2 hero citizens (Tc is built around 4:40)

Sheet Oranos
A1: Standard Opener | B1: Total Distribution (X means all vills go here)
A2: Description | B2: Food | C2: Wood | D2: Gold
A3: First two citizens to food | B3: 2 | C3: 0 | D3: 0
A4: Next to gold (Build a manor with him) | B4: 2 | C4: 0 | D4: 1
A5: Next to wood | B5: 2 | C5: 1 | D5: 1
A6: Rest to food | B6: X | C6: 1 | D6: 1
A7: You can either advance at 3:30 or 4:00, choice is yours. Personally I think 4:00 is better in most circumstances.

Sheet Gaia
A1: Standard Opener | B1: Total Distribution (X means all vills go here)
B2: Food | C2: Wood | D2: Gold
A3: first two to food, build economic guild with one and research pick axe/handaxe | B3: 2 | C3: 0 | D3: 0
A4: vill to gold | B4: 2 | C4: 0 | D4: 1
A5: vill to wood | B5: 2 | C5: 1 | D5: 1
A6: build manor with gold vill
A7: rest to food and when you have 150 gold switch the vill to wood and build temple once you have enough | B7: X | C7: 1 | D7: 1

Sheet Infantry Tier List
B1: Berserk | C1: Hirdman | D1: Huskarl | E1: Throwing Axemen | F1: Hoplite | G1: Hypapist | H1: Myrmidon | I1: Axemen | J1: Spearman | K1: Destroyer | L1: Fanatic | M1: Katapeltes | N1: Murmillo
A2: DPS | B2: 9.2857143 | C2: 4 | D2: 7 | E2: 4 | F2: 7.5 | G2: 5 | H2: 6.4285714 | I2: 5 | J2: 6 | K2: 5 | L2: 8 | M2: 5 | N2: 8.75
A3: Special/Bonus | B3: 1.5X vs Buildings | C3: 4x vs cavalry | D3: 2x vs archers | E3: 3X vs Infantry | F3: 1.25x vs cavalry | G3: 5x vs infantry | H3: DIVINE DAMAGE | I3: 5x vs infantry | J3: 1.75x vs cavalry | K3: 6x vs buildings | L3: 2x vs infantry 2x vs cavalry | M3: 4x vs cavalry
A4: HP (Per Cost) | B4: 1.0625 | C4: 1.125 | D4: 1 | E4: 0.72222222 | F4: 1.2777778 | G4: 1.1176471 | H4: 1 | I4: 1 | J4: 1.0714286 | K4: 1.1538462 | L4: 1.0769231 | M4: 1.2105263 | N4: 1.2941176
A5: HP | B5: 85 | C5: 90 | D5: 115 | E5: 65 | F5: 115 | G5: 95 | H5: 120 | I5: 70 | J5: 75 | K5: 150 | L5: 140 | M5: 115 | N5: 110
A6: Pierce Armor | B6: 0.1 | C6: 0.05 | D6: 0.6 | E6: 0.1 | F6: 0.15 | G6: 0.1 | H6: 0.2 | I6: 0.05 | J6: 0.15 | K6: 0.7 | L6: 0.15 | M6: 0.1 | N6: 0.1
A7: Hack Armor | B7: 0.35 | C7: 0.35 | D7: 0.1 | E7: 0.3 | F7: 0.4 | G7: 0.35 | H7: 0.4 | I7: 0.4 | J7: 0.4 | K7: 0.3 | L7: 0.4 | M7: 0.35 | N7: 0.4
A8: Speed | B8: 4.8 | C8: 4.8 | D8: 5 | E8: 4 | F8: 4.2 | G8: 4.3 | H8: 4.3 | I8: 4.3 | J8: 5 | K8: 3.6 | L8: 4.3 | M8: 4.5 | N8: 4.5
E9: RANGED
D11: =75+40 -> 115 | K11: =D11*5 -> 575
D12: =90 -> 90 | K12: =D12*6 -> 540
F13: =90*20 -> 1800 | H13: =90*20 -> 1800
F14: =130*14 -> 1820 | H14: =120*15 -> 1800

Sheet Ranged Tier List
B1: Godi (Hero) | C1: Throwing Axemen | D1: Toxotes | E1: Peltast | F1: Gastraphetoros | G1: Chariot Archer | H1: Slinger | I1: Arcus | J1: Cheiroballista | K1: Turma
A2: DPS (Per Cost) | B2: 0.036111111 | C2: 0.044444444 | D2: 0.066666667 | E2: 0.037037037 | F2: 0.035714286 | G2: 0.047619048 | H2: 0.035294118 | I2: 0.052631579 | J2: 0.027906977 | K2: 0.035947712
A3: Range | B3: 16 | C3: 10 | D3: 15 | E3: 18 | F3: 23 | G3: 20 | H3: 17 | I3: 20 | J3: 20 | K3: 12
A4: HP (Per Cost) | B4: 0.70833333 | C4: 0.72222222 | D4: 0.72222222 | E4: 0.77777778 | F4: 0.375 | G4: 0.67857143 | H4: 0.76470588 | I4: 0.68421053 | J4: 0.39534884 | K4: 0.94117647
A5: Speed | B5: 4 | C5: 4 | D5: 4 | E5: 4 | F5: 3.8 | G5: 5 | H5: 4 | I5: 4 | J5: 3.8 | K5: 5.5
A6: Special/Bonus | B6: 5.5x vs MU | C6: 3X vs Infantry | D6: 1.25X vs Infantry | E6: 4X vs ranged | F6: 8x vs buildings | G6: 1.25X vs Infantry | H6: 3x vs ranged | I6: 1.25X vs Infantry | J6: 3.5x infantry and 3x vs ships | K6: 4x vs ranged

Sheet Cav Tier List
B1: Raiding Cav | C1: Jarl | D1: Hippeus | E1: Prodromos | F1: Hetairos | G1: Camel Rider | H1: War Elephant | I1: Contarius
A2: Speed | B2: 6 | C2: 4.8 | D2: 5.5 | E2: 6 | F2: 5 | G2: 6 | H2: 2.9 | I2: 5.8
A3: Survivability | B3: 1.49 | C3: 1.8 | D3: 1.56 | E3: 1.41 | F3: 1.4 | G3: 1.41 | H3: 3.51 | I3: 1.79
A4: Damage | B4: 0.083 | C4: 0.077 | D4: 0.083 | E4: 0.056 | F4: 0.071 | G4: 0.067 | H4: 0.084 | I4: 0.09
A5: Special/Bonus Damage | B5: 1.5X Archers | C5: None | D5: 1.5X Archers | E5: 3.5X Cavalry | F5: Splash Damage | G5: 2X Cavalry | H5: 3X Buildings | I5: 1.5X Archers

Sheet TC Timing
A1: 0 | B1: 4 | E1: 0 | F1: 4
A2: 0.00017361111 | B2: 1 | C2: =SUM($B$1:B2) -> 5 | E2: 0.00017361111 | F2: 1 | G2: =SUM($F$1:F2) -> 5
A3: =A2+0.000173611111111111 -> 0.00034722222 | B3: 1 | C3: =SUM($B$1:B3) -> 6 | E3: =E2+0.000173611111111111 -> 0.00034722222 | F3: 1 | G3: =SUM($F$1:F3) -> 6
A4: =A3+0.000173611111111111 -> 0.00052083333 | B4: 1 | C4: =SUM($B$1:B4) -> 7 | E4: =E3+0.000173611111111111 -> 0.00052083333 | F4: 1 | G4: =SUM($F$1:F4) -> 7
A5: =A4+0.000173611111111111 -> 0.00069444444 | B5: 1 | C5: =SUM($B$1:B5) -> 8 | E5: =E4+0.000173611111111111 -> 0.00069444444 | F5: 1 | G5: =SUM($F$1:F5) -> 8
A6: =A5+0.000173611111111111 -> 0.00086805556 | B6: 1 | C6: =SUM($B$1:B6) -> 9 | E6: =E5+0.000173611111111111 -> 0.00086805556 | F6: 1 | G6: =SUM($F$1:F6) -> 9
A7: =A6+0.000173611111111111 -> 0.0010416667 | B7: 1 | C7: =SUM($B$1:B7) -> 10 | E7: =E6+0.000173611111111111 -> 0.0010416667 | F7: 1 | G7: =SUM($F$1:F7) -> 10
A8: =A7+0.000173611111111111 -> 0.0012152778 | B8: 1 | C8: =SUM($B$1:B8) -> 11 | E8: =E7+0.000173611111111111 -> 0.0012152778 | F8: 1 | G8: =SUM($F$1:F8) -> 11
A9: =A8+0.000173611111111111 -> 0.0013888889 | B9: 1 | C9: =SUM($B$1:B9) -> 12 | E9: =E8+0.000173611111111111 -> 0.0013888889 | F9: 1 | G9: =SUM($F$1:F9) -> 12
A10: =A9+0.000173611111111111 -> 0.0015625 | B10: 1 | C10: =SUM($B$1:B10) -> 13 | E10: =E9+0.000173611111111111 -> 0.0015625 | F10: 1 | G10: =SUM($F$1:F10) -> 13
A11: =A10+0.000173611111111111 -> 0.0017361111 | B11: 1 | C11: =SUM($B$1:B11) -> 14 | E11: =E10+0.000173611111111111 -> 0.0017361111 | F11: 1 | G11: =SUM($F$1:F11) -> 14
A12: =A11+0.000173611111111111 -> 0.0019097222 | B12: 1 | C12: =SUM($B$1:B12) -> 15 | E12: =E11+0.000173611111111111 -> 0.0019097222 | F12: 1 | G12: =SUM($F$1:F12) -> 15
A13: =A12+0.000173611111111111 -> 0.0020833333 | B13: 1 | C13: =SUM($B$1:B13) -> 16 | E13: =E12+0.000173611111111111 -> 0.0020833333 | F13: 1 | G13: =SUM($F$1:F13) -> 16
A14: =A13+0.000173611111111111 -> 0.0022569444 | B14: 1 | C14: =SUM($B$1:B14) -> 17 | E14: =E13+0.000173611111111111 -> 0.0022569444 | F14: 1 | G14: =SUM($F$1:F14) -> 17
A15: =A14+0.000173611111111111 -> 0.0024305556 | B15: 1 | C15: =SUM($B$1:B15) -> 18 | E15: =E14+0.000173611111111111 -> 0.0024305556 | F15: 1 | G15: =SUM($F$1:F15) -> 18
A16: =A15+0.000173611111111111 -> 0.0026041667 | C16: =SUM($B$1:B16) -> 18 | E16: =E15+0.000173611111111111 -> 0.0026041667 | F16: 1 | G16: =SUM($F$1:F16) -> 19
A17: =A16+0.000173611111111111 -> 0.0027777778 | C17: =SUM($B$1:B17) -> 18 | E17: =E16+0.000173611111111111 -> 0.0027777778 | F17: 1 | G17: =SUM($F$1:F17) -> 20
A18: =A17+0.000173611111111111 -> 0.0029513889 | B18: 1 | C18: =SUM($B$1:B18) -> 19 | E18: =E17+0.000173611111111111 -> 0.0029513889 | G18: =SUM($F$1:F18) -> 20
A19: =A18+0.000173611111111111 -> 0.003125 | B19: 1 | C19: =SUM($B$1:B19) -> 20 | E19: =E18+0.000173611111111111 -> 0.003125 | G19: =SUM($F$1:F19) -> 20
A20: =A19+0.000173611111111111 -> 0.0032986111 | B20: 2 | C20: =SUM($B$1:B20) -> 22 | E20: =E19+0.000173611111111111 -> 0.0032986111 | F20: 1 | G20: =SUM($F$1:F20) -> 21
A21: =A20+0.000173611111111111 -> 0.0034722222 | B21: 2 | C21: =SUM($B$1:B21) -> 24 | E21: =E20+0.000173611111111111 -> 0.0034722222 | F21: 1 | G21: =SUM($F$1:F21) -> 22
A22: =A21+0.000173611111111111 -> 0.0036458333 | B22: 2 | C22: =SUM($B$1:B22) -> 26 | E22: =E21+0.000173611111111111 -> 0.0036458333 | F22: 2 | G22: =SUM($F$1:F22) -> 24
A23: =A22+0.000173611111111111 -> 0.0038194444 | B23: 2 | C23: =SUM($B$1:B23) -> 28 | E23: =E22+0.000173611111111111 -> 0.0038194444 | F23: 2 | G23: =SUM($F$1:F23) -> 26
A24: =A23+0.000173611111111111 -> 0.0039930556 | B24: 2 | C24: =SUM($B$1:B24) -> 30 | E24: =E23+0.000173611111111111 -> 0.0039930556 | F24: 2 | G24: =SUM($F$1:F24) -> 28
A25: =A24+0.000173611111111111 -> 0.0041666667 | B25: 2 | C25: =SUM($B$1:B25) -> 32 | E25: =E24+0.000173611111111111 -> 0.0041666667 | F25: 2 | G25: =SUM($F$1:F25) -> 30
A26: =A25+0.000173611111111111 -> 0.0043402778 | B26: 2 | C26: =SUM($B$1:B26) -> 34 | E26: =E25+0.000173611111111111 -> 0.0043402778 | F26: 2 | G26: =SUM($F$1:F26) -> 32
A27: =A26+0.000173611111111111 -> 0.0045138889 | B27: 2 | C27: =SUM($B$1:B27) -> 36 | E27: =E26+0.000173611111111111 -> 0.0045138889 | F27: 2 | G27: =SUM($F$1:F27) -> 34
A28: =A27+0.000173611111111111 -> 0.0046875 | B28: 2 | C28: =SUM($B$1:B28) -> 38 | E28: =E27+0.000173611111111111 -> 0.0046875 | F28: 2 | G28: =SUM($F$1:F28) -> 36
A29: =A28+0.000173611111111111 -> 0.0048611111 | B29: 2 | C29: =SUM($B$1:B29) -> 40 | E29: =E28+0.000173611111111111 -> 0.0048611111 | F29: 2 | G29: =SUM($F$1:F29) -> 38
A30: =A29+0.000173611111111111 -> 0.0050347222 | B30: 2 | C30: =SUM($B$1:B30) -> 42 | E30: =E29+0.000173611111111111 -> 0.0050347222 | F30: 2 | G30: =SUM($F$1:F30) -> 40
A31: =A30+0.000173611111111111 -> 0.0052083333 | B31: 2 | C31: =SUM($B$1:B31) -> 44 | E31: =E30+0.000173611111111111 -> 0.0052083333 | F31: 2 | G31: =SUM($F$1:F31) -> 42
... A55: =A54+0.000173611111111111 -> 0.009375 | B55: 2 | C55: =SUM($B$1:B55) -> 92 | E55: =E54+0.000173611111111111 -> 0.009375 | F55: 2 | G55: =SUM($F$1:F55) -> 90

Sheet Calculations
A1: TC Build Time | D1: Vills working | H1: Vills after building TC | J1: Summary
A2: Vills | B2: Build Time | C2: Reduction | D2: # of Vills | E2: Gather Rate | F2: Time | G2: Total | H2: Time | I2: Gathered | J2: Total
A3: 1 | B3: 150 | C3: =1-(B4/B3) -> 0.37333333 | D3: =10-A3 -> 9 | E3: 0.85 | F3: 150 | G3: =D3*E3*F3 -> 1147.5 | H3: =F3-(B3) -> 0 | I3: =A3*E3*H3 -> 0 | J3: =G3+I3 -> 1147.5
A4: 2 | B4: 94 | C4: =1-(B5/B4) -> 0.15957447 | D4: =10-A4 -> 8 | E4: 0.85 | F4: 150 | G4: =D4*E4*F4 -> 1020 | H4: =F4-B4-10 -> 46 | I4: =A4*E4*H4 -> 78.2 | J4: =G4+I4 -> 1098.2
A5: 3 | B5: 79 | C5: =1-(B6/B5) -> 0.13924051 | D5: =10-A5 -> 7 | E5: 0.85 | F5: 150 | G5: =D5*E5*F5 -> 892.5 | H5: =F5-B5-10 -> 61 | I5: =A5*E5*H5 -> 155.55 | J5: =G5+I5 -> 1048.05
A6: 4 | B6: 68 | C6: =1-(B7/B6) -> 0.11764706 | D6: =10-A6 -> 6 | E6: 0.85 | F6: 150 | G6: =D6*E6*F6 -> 765 | H6: =F6-B6-10 -> 72 | I6: =A6*E6*H6 -> 244.8 | J6: =G6+I6 -> 1009.8
A7: 5 | B7: 60 | C7: =1-(B8/B7) -> 0.1 | D7: =10-A7 -> 5 | E7: 0.85 | F7: 150 | G7: =D7*E7*F7 -> 637.5 | H7: =F7-B7-10 -> 80 | I7: =A7*E7*H7 -> 340 | J7: =G7+I7 -> 977.5
A8: 6 | B8: 54 | C8: =1-(B9/B8) -> 0.11111111 | D8: =10-A8 -> 4 | E8: 0.85 | F8: 150 | G8: =D8*E8*F8 -> 510 | H8: =F8-B8-10 -> 86 | I8: =A8*E8*H8 -> 438.6 | J8: =G8+I8 -> 948.6
A9: 7 | B9: 48 | C9: =1-(B10/B9) -> 0.083333333 | D9: =10-A9 -> 3 | E9: 0.85 | F9: 150 | G9: =D9*E9*F9 -> 382.5 | H9: =F9-B9-10 -> 92 | I9: =A9*E9*H9 -> 547.4 | J9: =G9+I9 -> 929.9
A10: 8 | B10: 44 | C10: =1-(B11/B10) -> 0.090909091 | D10: =10-A10 -> 2 | E10: 0.85 | F10: 150 | G10: =D10*E10*F10 -> 255 | H10: =F10-B10-10 -> 96 | I10: =A10*E10*H10 -> 652.8 | J10: =G10+I10 -> 907.8
A11: 9 | B11: 40 | C11: =1-(B12/B11) -> 0.05 | D11: =10-A11 -> 1 | E11: 0.85 | F11: 150 | G11: =D11*E11*F11 -> 127.5 | H11: =F11-B11-10 -> 100 | I11: =A11*E11*H11 -> 765 | J11: =G11+I11 -> 892.5
A12: 10 | B12: 38 | C12: =1-(B13/B12) -> 0.078947368 | D12: =10-A12 -> 0 | E12: 0.85 | F12: 150 | G12: =D12*E12*F12 -> 0 | H12: =F12-B12-10 -> 102 | I12: =A12*E12*H12 -> 867 | J12: =G12+I12 -> 867
A13: 11 | B13: 35
